Workbook

Sheet Operating Assumptions
A1: Operating Assumptions & Controls
A3: Project Controls
A4: Tunnel Length (ft) | B4: 120 | C4: Input
A5: Vacuum Stalls | B5: 18 | C5: Input
A6: Self-Serve Bays | B6: 0 | C6: Input
A7: Base Case Total Project Cost | B7: 8750000 | C7: Input
A8: Senior Debt % | B8: 0.7 | C8: Input
A9: Senior Debt | B9: =B7*B8 -> 6125000 | C9: Formula
A10: Equity Contribution | B10: =B7-B9 -> 2625000 | C10: Formula
A13: Operating Revenue Build
A14: Retail Cars per Day | B14: 260 | C14: Input
A15: Average Retail Ticket ($) | B15: 20 | C15: Input
A16: Membership Count | B16: 3100 | C16: Input
A17: Average Monthly Member Price ($) | B17: 31 | C17: Input
A18: Other Revenue ($) | B18: 0 | C18: Input
A19: Annual Retail Revenue | B19: =B14*B15*365 -> 1898000 | C19: Formula
A20: Annual Membership Revenue | B20: =B16*B17*12 -> 1153200 | C20: Formula
A21: Total Annual Revenue | B21: =SUM(B19:B20) -> 3051200 | C21: Formula
A22: EBITDA Margin | B22: 0.65 | C22: Input
A23: EBITDA | B23: =B21*B22 -> 1983280 | C23: Formula
A24: Senior Debt (link cell) | B24: =B9 -> 6125000 | C24: linked
A25: Equity Contribution (link cell) | B25: =B10 -> 2625000 | C25: linked
A27: Financing & Valuation Assumptions
A28: Interest Rate | B28: 0.07 | C28: Input
A29: Amortization (Years) | B29: 25 | C29: Input
A30: Refi LTV | B30: 0.7 | C30: Input
A31: Refi Multiple | B31: 6 | C31: Input
A32: Exit Multiple | B32: 6.5 | C32: Input
A33: Preferred Return | B33: 0.08 | C33: Input

Sheet Sources & Uses
A1: Sources & Uses (Base Case)
A3: Sources
A4: Senior Debt (70%) | B4: ='Operating Assumptions'!B24 -> 6125000 | C4: Linked from controls
A5: Equity Contribution | B5: ='Operating Assumptions'!B25 -> 2625000
A6: Total Sources | B6: =SUM(B4:B5) -> 8750000
A8: Detailed Uses
A9: Category | B9: Line Item | C9: Estimated Cost ($)
A10: LAND & DUE DILIGENCE | B10: Land Acquisition (1.5 acres) | C10: 1600000
A11: LAND & DUE DILIGENCE | B11: Survey, Title, Legal, Closing | C11: 35000
A12: LAND & DUE DILIGENCE | B12: Environmental (Phase I) | C12: 20000
A13: LAND & DUE DILIGENCE | B13: Geotechnical / Soil Report | C13: 15000
A14: LAND & DUE DILIGENCE | B14: Site Due Diligence Contingency | C14: 30000
A15: LAND & DUE DILIGENCE | B15: SUBTOTAL – LAND & DD | C15: =SUM(C10:C14) -> 1700000
A17: CONSTRUCTION – SITE WORK | B17: Clearing, Grading, Earthwork | C17: 140000
A18: CONSTRUCTION – SITE WORK | B18: Underground Utilities (Water, Sewer, Elec) | C18: 300000
A19: CONSTRUCTION – SITE WORK | B19: Stormwater & Detention | C19: 220000
A20: CONSTRUCTION – SITE WORK | B20: Concrete Paving (Heavy Duty) | C20: 540000
A21: CONSTRUCTION – SITE WORK | B21: Curbs, Sidewalks, ADA | C21: 110000
A22: CONSTRUCTION – SITE WORK | B22: Landscaping & Irrigation | C22: 80000
A23: CONSTRUCTION – SITE WORK | B23: Vacuum Plaza Foundations / Electrical | C23: 160000
A24: CONSTRUCTION – SITE WORK | B24: SUBTOTAL – SITE WORK | C24: =SUM(C17:C23) -> 1550000
A26: CONSTRUCTION – VERTICAL | B26: Tunnel Building Structure (120 ft) | C26: 700000
A27: CONSTRUCTION – VERTICAL | B27: Equipment / Mechanical Room | C27: 240000
A28: CONSTRUCTION – VERTICAL | B28: Vacuum Canopy Structure (18 stalls) | C28: 260000
A29: CONSTRUCTION – VERTICAL | B29: Office / Back Room / Façade | C29: 100000
A30: CONSTRUCTION – VERTICAL | B30: SUBTOTAL – VERTICAL CONSTRUCTION | C30: =SUM(C26:C29) -> 1300000
A32: EQUIPMENT – TUNNEL & VACS | B32: Conveyor & Tunnel Equipment | C32: 930000
A33: EQUIPMENT – TUNNEL & VACS | B33: Prep Arches, Mitters & Brushes | C33: 220000
A34: EQUIPMENT – TUNNEL & VACS | B34: Dryer System (High Performance) | C34: 320000
A35: EQUIPMENT – TUNNEL & VACS | B35: Water Reclaim & RO System | C35: 250000
A36: EQUIPMENT – TUNNEL & VACS | B36: Chemical Delivery Systems | C36: 100000
A37: EQUIPMENT – TUNNEL & VACS | B37: POS / Pay Stations | C37: 80000
A38: EQUIPMENT – TUNNEL & VACS | B38: Vacuum Motors / Controls / Manifolds | C38: 100000
A39: EQUIPMENT – TUNNEL & VACS | B39: SUBTOTAL – TUNNEL & VAC EQUIPMENT | C39: =SUM(C32:C38) -> 2000000
A41: SOFT COSTS | B41: Architectural & Engineering | C41: 230000
A42: SOFT COSTS | B42: Permits, Impact & Tap Fees | C42: 120000
A43: SOFT COSTS | B43: Traffic Study & Municipal Fees | C43: 60000
A44: SOFT COSTS | B44: Insurance During Construction | C44: 50000
A45: SOFT COSTS | B45: Legal, Accounting & Consulting | C45: 90000
A46: SOFT COSTS | B46: SUBTOTAL – SOFT COSTS | C46: =SUM(C41:C45) -> 550000
...

Sheet Construction Draw Schedule
A1: Construction Draw Schedule
A3: Phase | B3: Cost ($) | C3: Timing
A4: Land Acquisition & Due Diligence | B4: ='Sources & Uses'!C15 -> 1700000 | C4: Month 0
A5: Site Work | B5: ='Sources & Uses'!C24 -> 1550000 | C5: Months 1–3
A6: Vertical Construction | B6: ='Sources & Uses'!C30 -> 1300000 | C6: Months 3–7
A7: Equipment Install (Tunnel + 18 Vacs) | B7: ='Sources & Uses'!C39 -> 2000000 | C7: Months 6–9
A8: Soft Costs | B8: ='Sources & Uses'!C46 -> 550000 | C8: Throughout
A9: Contingency / Working Capital | B9: ='Sources & Uses'!C52 -> 1650000 | C9: As Needed
A10: Total Uses | B10: ='Sources & Uses'!C55 -> 8750000

Sheet Interest Reserve
A1: Interest Reserve
A3: Reserve Assumptions
A4: Loan Amount | B4: ='Operating Assumptions'!B24 -> 6125000 | C4: Linked
A5: Interest Rate | B5: ='Operating Assumptions'!B28 -> 0.07 | C5: Linked
A6: Construction / Lease-up Period (Months) | B6: 10 | C6: Input
A7: Average Drawn % of Loan | B7: 0.55 | C7: Input
A8: Interest Reserve | B8: =B4*B5*B6/12*B7 -> 196510.42 | C8: Formula
A10: Note | B10: Reserve reflects average drawn balance during 10-month build.

Sheet Debt Service
A1: Debt Service
A3: Base Loan Metrics
A4: Loan Amount | B4: ='Operating Assumptions'!B24 -> 6125000
A5: Interest Rate | B5: ='Operating Assumptions'!B28 -> 0.07
A6: Amortization (Years) | B6: ='Operating Assumptions'!B29 -> 25
A7: Annual Debt Service | B7: =-PMT(B5/12,B6*12,B4)*12 -> 519482.71
A8: EBITDA | B8: ='Operating Assumptions'!B23 -> 1983280
A9: Debt Service Coverage Ratio | B9: =B8/B7 -> 3.8177979
A12: Refi Debt Metrics
A13: New Loan at Refi | B13: ='Refi Analysis'!B8 -> 8329776
A14: Annual Debt Service (Refi Loan) | B14: =-PMT('Operating Assumptions'!B28/12,'Operating Assumptions'!B29*12,B13)*12 -> 706477.49
A15: Distributable Cash Flow Post Refi | B15: ='Operating Assumptions'!B23-B14 -> 1276802.5

Sheet Credit Memo
A1: Credit Memo Summary
A3: Uses of funds consist of land acquisition and due diligence, full site development, vertical construction of a premium 120-foot express tunnel, installation of tunnel and vacuum equipment for 18 vacuum stalls, standard soft costs including architectural, engineering, permitting, and professional fees, and an appropriate contingency and operating reserve.
A5: Sources of funds include a senior secured construction loan representing approximately 70% of total project cost, with the remaining 30% funded by sponsor / investor equity. Equity is assumed to be contributed first, with loan proceeds drawn monthly on a reimbursable basis in accordance with the construction draw schedule.
A7: The underwriting assumes no self-service bays and a membership-driven express wash model. Stabilized operating assumptions target approximately $3.05 million of annual revenue and roughly 65% EBITDA margin.
A9: Refinancing is underwritten at a 6.0x EBITDA multiple and 70% loan-to-value. Resulting cash-out proceeds are assumed to be distributed first to investors, de-risking capital while preserving long-term upside.
A10: Key Metrics
A11: Total Project Cost | B11: ='Sources & Uses'!C55 -> 8750000
A12: Senior Debt | B12: ='Operating Assumptions'!B24 -> 6125000
A13: Equity | B13: ='Operating Assumptions'!B25 -> 2625000
A14: Revenue | B14: ='Operating Assumptions'!B21 -> 3051200
A15: EBITDA | B15: ='Operating Assumptions'!B23 -> 1983280
A16: Base DSCR | B16: ='Debt Service'!B9 -> 3.8177979

Sheet Refi Analysis
A1: Refinance Analysis
A3: Valuation & Proceeds
A4: EBITDA | B4: ='Operating Assumptions'!B23 -> 1983280
A5: Refi Multiple | B5: ='Operating Assumptions'!B31 -> 6
A6: Implied Value | B6: =B4*B5 -> 11899680
A7: Refi LTV | B7: ='Operating Assumptions'!B30 -> 0.7
A8: New Loan | B8: =B6*B7 -> 8329776
A9: Existing Debt (Conservative Takeout) | B9: ='Operating Assumptions'!B24 -> 6125000
A10: Cash Out at Refi | B10: =B8-B9 -> 2204776
A11: Investor Equity | B11: ='Operating Assumptions'!B25 -> 2625000
A12: % Investor Capital Returned | B12: =B10/B11 -> 0.83991467
A15: Post-Refi Cash Flow & Exit
A16: Annual Debt Service (Refi Loan) | B16: =-PMT('Operating Assumptions'!B28/12,'Operating Assumptions'!B29*12,B8)*12 -> 706477.49
A17: Distributable Cash Flow Post Refi | B17: ='Operating Assumptions'!B23-B16 -> 1276802.5
A18: Exit Multiple | B18: ='Operating Assumptions'!B32 -> 6.5
A19: Exit Value | B19: ='Operating Assumptions'!B23*B18 -> 12891320
A20: Net Sale Proceeds | B20: =B19-B8 -> 4561544

Sheet Returns
A1: Investor / Sponsor Waterfall Returns
B3: Year 0 | C3: Year 1 | D3: Year 2 (Refi) | E3: Year 3 | F3: Year 4 | G3: Year 5 (Exit)
A4: Year Fraction | B4: 0 | C4: 0.5 | D4: 1 | E4: 1 | F4: 1 | G4: 1
A5: Distribution Pool | B5: 0 | C5: ='Operating Assumptions'!B25*'Operating Assumptions'!B33*C4 -> 105000 | D5: ='Operating Assumptions'!B25*'Operating Assumptions'!B33*D4+'Refi Analysis'!B10 -> 2414776 | E5: ='Refi Analysis'!B17 -> 1276802.5 | F5: ='Refi Analysis'!B17 -> 1276802.5 | G5: ='Refi Analysis'!B17+'Refi Analysis'!B20 -> 5838346.5
A6: Beginning Unreturned Capital | B6: ='Operating Assumptions'!B25 -> 2625000 | C6: =B18 -> 2625000 | D6: =C18 -> 2625000 | E6: =D18 -> 420224 | F6: =E18 -> 0 | G6: =F18 -> 0
A7: Refi Capital Return | B7: 0 | C7: 0 | D7: =MIN(D6,'Refi Analysis'!B10) -> 2204776 | E7: 0 | F7: 0 | G7: 0
A8: Capital After Refi | B8: =B6-B7 -> 2625000 | C8: =C6-C7 -> 2625000 | D8: =D6-D7 -> 420224 | E8: =E6-E7 -> 420224 | F8: =F6-F7 -> 0 | G8: =G6-G7 -> 0
A9: Pref Due | B9: =B6*'Operating Assumptions'!B33*B4 -> 0 | C9: =C6*'Operating Assumptions'!B33*C4 -> 105000 | D9: =D6*'Operating Assumptions'!B33*D4 -> 210000 | E9: =E6*'Operating Assumptions'!B33*E4 -> 33617.92 | F9: =F6*'Operating Assumptions'!B33*F4 -> 0 | G9: =G6*'Operating Assumptions'!B33*G4 -> 0
A10: Pref Paid | B10: =MIN(MAX(0,B5-B7),B9) -> 0 | C10: =MIN(MAX(0,C5-C7),C9) -> 105000 | D10: =MIN(MAX(0,D5-D7),D9) -> 210000 | E10: =MIN(MAX(0,E5-E7),E9) -> 33617.92 | F10: =MIN(MAX(0,F5-F7),F9) -> 0 | G10: =MIN(MAX(0,G5-G7),G9) -> 0
A11: Cash After Pref | B11: =MAX(0,B5-B7-B10) -> 0 | C11: =MAX(0,C5-C7-C10) -> 0 | D11: =MAX(0,D5-D7-D10) -> 0 | E11: =MAX(0,E5-E7-E10) -> 1243184.6 | F11: =MAX(0,F5-F7-F10) -> 1276802.5 | G11: =MAX(0,G5-G7-G10) -> 5838346.5
A12: Pre-Flip Cash Used | B12: =IF(B8>0,MIN(B11,B8/0.4),0) -> 0 | C12: =IF(C8>0,MIN(C11,C8/0.4),0) -> 0 | D12: =IF(D8>0,MIN(D11,D8/0.4),0) -> 0 | E12: =IF(E8>0,MIN(E11,E8/0.4),0) -> 1050560 | F12: =IF(F8>0,MIN(F11,F8/0.4),0) -> 0 | G12: =IF(G8>0,MIN(G11,G8/0.4),0) -> 0
A13: Investor Pre-Flip Share | B13: =B12*0.4 -> 0 | C13: =C12*0.4 -> 0 | D13: =D12*0.4 -> 0 | E13: =E12*0.4 -> 420224 | F13: =F12*0.4 -> 0 | G13: =G12*0.4 -> 0
A14: Sponsor Pre-Flip Share | B14: =B12*0.6 -> 0 | C14: =C12*0.6 -> 0 | D14: =D12*0.6 -> 0 | E14: =E12*0.6 -> 630336 | F14: =F12*0.6 -> 0 | G14: =G12*0.6 -> 0
A15: Post-Flip Cash | B15: =MAX(0,B11-B12) -> 0 | C15: =MAX(0,C11-C12) -> 0 | D15: =MAX(0,D11-D12) -> 0 | E15: =MAX(0,E11-E12) -> 192624.59 | F15: =MAX(0,F11-F12) -> 1276802.5 | G15: =MAX(0,G11-G12) -> 5838346.5
A16: Investor Post-Flip Share | B16: =B15*0.2 -> 0 | C16: =C15*0.2 -> 0 | D16: =D15*0.2 -> 0 | E16: =E15*0.2 -> 38524.919 | F16: =F15*0.2 -> 255360.5 | G16: =G15*0.2 -> 1167669.3
A17: Sponsor Post-Flip Share | B17: =B15*0.8 -> 0 | C17: =C15*0.8 -> 0 | D17: =D15*0.8 -> 0 | E17: =E15*0.8 -> 154099.67 | F17: =F15*0.8 -> 1021442 | G17: =G15*0.8 -> 4670677.2
A18: Ending Unreturned Capital | B18: =MAX(0,B8-B13) -> 2625000 | C18: =MAX(0,C8-C13) -> 2625000 | D18: =MAX(0,D8-D13) -> 420224 | E18: =MAX(0,E8-E13) -> 0 | F18: =MAX(0,F8-F13) -> 0 | G18: =MAX(0,G8-G13) -> 0
A19: Investor Total Cash Flow | B19: =-'Operating Assumptions'!B25 -> -2625000 | C19: =C7+C10+C13+C16 -> 105000 | D19: =D7+D10+D13+D16 -> 2414776 | E19: =E7+E10+E13+E16 -> 492366.84 | F19: =F7+F10+F13+F16 -> 255360.5 | G19: =G7+G10+G13+G16 -> 1167669.3
A20: Sponsor Total Cash Flow | B20: 0 | C20: =C14+C17 -> 0 | D20: =D14+D17 -> 0 | E20: =E14+E17 -> 784435.67 | F20: =F14+F17 -> 1021442 | G20: =G14+G17 -> 4670677.2
A22: Investor IRR | B22: =IRR(B19:G19) -> 0.20283468
A23: Investor Equity Multiple | B23: =SUM(C19:G19)/ABS(B19) -> 1.6895896
A24: Sponsor Distributions | B24: =SUM(C20:G20) -> 6476554.9

Sheet Investor Summary
A1: Investor Summary
A3: Key Investor Outputs
A4: Equity Invested | B4: ='Operating Assumptions'!B25 -> 2625000
A5: Refi Cash Returned | B5: ='Refi Analysis'!B10 -> 2204776
A6: % Capital Returned at Refi | B6: ='Refi Analysis'!B12 -> 0.83991467
A7: Annual Cash Flow Post Refi | B7: ='Refi Analysis'!B17 -> 1276802.5
A8: 5-Year Investor IRR | B8: =Returns!B22 -> 0.20283468
A9: Equity Multiple | B9: =Returns!B23 -> 1.6895896
A12: Year-by-Year Investor Cash Flow
B13: Year 0 | C13: Year 1 | D13: Year 2 (Refi) | E13: Year 3 | F13: Year 4 | G13: Year 5 (Exit)
A14: Investor CF | B14: =Returns!B19 -> -2625000 | C14: =Returns!C19 -> 105000 | D14: =Returns!D19 -> 2414776 | E14: =Returns!E19 -> 492366.84 | F14: =Returns!F19 -> 255360.5 | G14: =Returns!G19 -> 1167669.3
